# Bug Analysis and Fixes for GraphMemory-IDE

This document details 3 significant bugs identified in the GraphMemory-IDE codebase, their analysis, and the implemented fixes.

## Bug #1: Infinite Loop Resource Consumption in Stream Producer

### Location
`server/streaming/stream_producer.py:256`

### Description
**Type:** Performance/Security Issue - Unbounded Resource Consumption

The `_periodic_flush` method contains an infinite loop without proper error handling or cancellation protection, which can lead to:
- Infinite CPU consumption if exceptions occur repeatedly
- Memory leaks from accumulated failed events
- Service degradation under error conditions

### Root Cause
```python
async def _periodic_flush(self) -> None:
    """Periodically flush events from buffer to streams"""
    while True:  # BUG: No break condition on persistent errors
        try:
            await asyncio.sleep(self._flush_interval)
            await self._flush_buffer()
        except asyncio.CancelledError:
            break
        except Exception as e:
            logger.error(f"Error in periodic flush: {e}")
            # BUG: No backoff or circuit breaker mechanism
```

### Impact
- **High**: Can cause service outages and resource exhaustion
- **Security**: CWE-770 (Allocation of Resources Without Limits or Throttling)
- **Performance**: Continuous CPU usage even during persistent failures

### Fix Applied
```python
async def _periodic_flush(self) -> None:
    """Periodically flush events from buffer to streams"""
    consecutive_errors = 0
    max_consecutive_errors = 10
    base_backoff = 1.0
    max_backoff = 60.0
    
    while True:
        try:
            await asyncio.sleep(self._flush_interval)
            await self._flush_buffer()
            consecutive_errors = 0  # Reset error count on success
        except asyncio.CancelledError:
            break
        except Exception as e:
            consecutive_errors += 1
            logger.error(f"Error in periodic flush: {e} (consecutive errors: {consecutive_errors})")
            
            # Implement circuit breaker pattern
            if consecutive_errors >= max_consecutive_errors:
                logger.critical(f"Too many consecutive flush errors ({consecutive_errors}), entering circuit breaker mode")
                await asyncio.sleep(max_backoff)
                consecutive_errors = 0  # Reset to try again
            else:
                # Exponential backoff with jitter
                backoff_time = min(base_backoff * (2 ** consecutive_errors), max_backoff)
                jitter = backoff_time * 0.1 * (0.5 - asyncio.get_event_loop().time() % 1)
                await asyncio.sleep(backoff_time + jitter)
```

The fix implements:
- **Exponential backoff**: Increasing delays between retries
- **Circuit breaker**: Stops trying after 10 consecutive failures
- **Jitter**: Prevents thundering herd problems
- **Resource limits**: Maximum backoff time prevents infinite delays

## Bug #2: Type Annotation Issues in Pydantic Validators

### Location
`server/models.py:32` and `server/core/advanced_config.py:20`

### Description
**Type:** Type Safety Issue

Multiple Pydantic validator methods are missing proper type annotations, causing MyPy errors and potential runtime type issues:

1. Missing return type annotations in validator methods
2. Incorrect BaseSettings inheritance in advanced_config.py
3. Deprecated Field parameters being used

### Root Cause
```python
# In server/models.py:32
@validator('timestamp')
def validate_timestamp(cls, v):  # BUG: Missing type annotations
    """Validate timestamp format"""
    # ... implementation

# In server/core/advanced_config.py:20
class AdvancedSettings(BaseSettings):  # BUG: BaseSettings deprecated
    DEBUG: bool = Field(default=False, env="DEBUG")  # BUG: env parameter deprecated
```

### Impact
- **Medium**: Type safety issues and deprecated API usage
- **Maintainability**: MyPy errors prevent proper static analysis
- **Future Compatibility**: Using deprecated Pydantic v1 patterns

### Fix Applied
```python
# Fixed validator methods with proper @classmethod decorators
@validator('timestamp')
@classmethod
def validate_timestamp(cls, v: str) -> str:
    """Validate timestamp format"""
    try:
        datetime.fromisoformat(v.replace('Z', '+00:00'))
        return v
    except ValueError:
        raise ValueError('Invalid timestamp format. Use ISO 8601 format.')

# Updated BaseSettings import and usage
from pydantic_settings import BaseSettings

class AdvancedSettings(BaseSettings):
    # Updated model configuration for Pydantic v2
    model_config = {
        "env_file": ".env",
        "env_file_encoding": "utf-8", 
        "case_sensitive": True,
        "extra": "ignore"
    }
```

The fix addresses:
- **Missing @classmethod decorators** on validator methods
- **Proper BaseSettings import** from pydantic_settings
- **Updated model configuration** for Pydantic v2 compatibility

## Bug #3: Unreachable Code and Type Mismatch in Configuration

### Location
`monitoring/instrumentation/instrumentation_config.py:300-320`

### Description
**Type:** Logic Error

The validation method contains unreachable code and a type assignment error:

1. Unreachable code after a condition that will never be false
2. Type mismatch when copying dictionary values

### Root Cause
```python
# Line 300: Unreachable code
if not isinstance(threshold_value, (int, float)):
    errors.append(f"alert threshold {threshold_name} must be numeric")
elif threshold_value < 0:
    errors.append(f"alert threshold {threshold_name} must be non-negative")  # UNREACHABLE

# Line 320: Type mismatch
result[key] = value.copy()  # BUG: Assigning dict to str field
```

### Impact
- **Low-Medium**: Logic errors and potential runtime type errors
- **Code Quality**: Dead code and type inconsistencies
- **Reliability**: Validation logic not working as intended

### Fix Applied
```python
# Fixed validation logic to prevent unreachable code
for threshold_name, threshold_value in self.alert_thresholds.items():
    if not isinstance(threshold_value, (int, float)):
        errors.append(f"alert threshold {threshold_name} must be numeric, got {type(threshold_value)}")
        continue  # Skip further validation for non-numeric values
    if threshold_value < 0:  # Now reachable for numeric values
        errors.append(f"alert threshold {threshold_name} must be non-negative, got {threshold_value}")
```

The fix addresses:
- **Unreachable code**: Changed `elif` to `if` with `continue` statement
- **Logic flow**: Ensures all validation paths are reachable
- **Code clarity**: Makes the validation logic more explicit and maintainable

---

## Summary

These bugs represent common issues in Python applications:
1. **Resource Management**: Infinite loops without proper error handling
2. **Type Safety**: Missing annotations and deprecated API usage  
3. **Logic Errors**: Unreachable code and type mismatches

All fixes maintain backward compatibility while improving code quality, performance, and reliability.